<?xml version="1.0"?>
<robot name="mecanum_robot" xmlns:xacro="http://www.ros.org/wiki/xacro">

  <!-- Base Link -->
  <link name="base_link">
    <visual>
      <origin xyz="0 0 0.05" rpy="0 0 0"/>
      <geometry>
        <box size="0.3 0.2 0.1"/>
      </geometry>
      <material name="blue">
        <color rgba="0.0 0.0 0.8 1.0"/>
      </material>
    </visual>
    <collision>
      <origin xyz="0 0 0.05" rpy="0 0 0"/>
      <geometry>
        <box size="0.3 0.2 0.1"/>
      </geometry>
    </collision>
    <inertial>
      <origin xyz="0 0 0.05" rpy="0 0 0"/>
      <mass value="1.0"/>
      <inertia ixx="0.01" ixy="0.0" ixz="0.0"
               iyy="0.01" iyz="0.0"
               izz="0.01"/>
    </inertial>
  </link>

  <!-- Front Left Wheel -->
  <link name="front_left_wheel">
    <visual>
      <origin xyz="0 0 0" rpy="1.5708 0 0"/>
      <geometry>
        <cylinder length="0.03" radius="0.05"/>
      </geometry>
      <material name="red">
        <color rgba="0.8 0.0 0.0 1.0"/>
      </material>
    </visual>
    <collision>
      <origin xyz="0 0 0" rpy="1.5708 0 0"/>
      <geometry>
        <cylinder length="0.03" radius="0.05"/>
      </geometry>
    </collision>
    <inertial>
      <origin xyz="0 0 0" rpy="1.5708 0 0"/>
      <mass value="0.1"/>
      <inertia ixx="0.001" ixy="0.0" ixz="0.0"
               iyy="0.001" iyz="0.0"
               izz="0.001"/>
    </inertial>
  </link>

  <!-- Front Right Wheel -->
  <link name="front_right_wheel">
    <visual>
      <origin xyz="0 0 0" rpy="1.5708 0 0"/>
      <geometry>
        <cylinder length="0.03" radius="0.05"/>
      </geometry>
      <material name="red">
        <color rgba="0.8 0.0 0.0 1.0"/>
      </material>
    </visual>
    <collision>
      <origin xyz="0 0 0" rpy="1.5708 0 0"/>
      <geometry>
        <cylinder length="0.03" radius="0.05"/>
      </geometry>
    </collision>
    <inertial>
      <origin xyz="0 0 0" rpy="1.5708 0 0"/>
      <mass value="0.1"/>
      <inertia ixx="0.001" ixy="0.0" ixz="0.0"
               iyy="0.001" iyz="0.0"
               izz="0.001"/>
    </inertial>
  </link>

  <!-- Rear Left Wheel -->
  <link name="rear_left_wheel">
    <visual>
      <origin xyz="0 0 0" rpy="1.5708 0 0"/>
      <geometry>
        <cylinder length="0.03" radius="0.05"/>
      </geometry>
      <material name="red">
        <color rgba="0.8 0.0 0.0 1.0"/>
      </material>
    </visual>
    <collision>
      <origin xyz="0 0 0" rpy="1.5708 0 0"/>
      <geometry>
        <cylinder length="0.03" radius="0.05"/>
      </geometry>
    </collision>
    <inertial>
      <origin xyz="0 0 0" rpy="1.5708 0 0"/>
      <mass value="0.1"/>
      <inertia ixx="0.001" ixy="0.0" ixz="0.0"
               iyy="0.001" iyz="0.0"
               izz="0.001"/>
    </inertial>
  </link>

  <!-- Rear Right Wheel -->
  <link name="rear_right_wheel">
    <visual>
      <origin xyz="0 0 0" rpy="1.5708 0 0"/>
      <geometry>
        <cylinder length="0.03" radius="0.05"/>
      </geometry>
      <material name="red">
        <color rgba="0.8 0.0 0.0 1.0"/>
      </material>
    </visual>
    <collision>
      <origin xyz="0 0 0" rpy="1.5708 0 0"/>
      <geometry>
        <cylinder length="0.03" radius="0.05"/>
      </geometry>
    </collision>
    <inertial>
      <origin xyz="0 0 0" rpy="1.5708 0 0"/>
      <mass value="0.1"/>
      <inertia ixx="0.001" ixy="0.0" ixz="0.0"
               iyy="0.001" iyz="0.0"
               izz="0.001"/>
    </inertial>
  </link>

  <!-- Ultrasonic Sensor Link -->
  <link name="ultrasonic_link">
    <visual>
      <origin xyz="0 0 0" rpy="0 0 0"/>
      <geometry>
        <box size="0.04 0.02 0.02"/>
      </geometry>
      <material name="green">
        <color rgba="0.0 0.8 0.0 1.0"/>
      </material>
    </visual>
    <collision>
      <origin xyz="0 0 0" rpy="0 0 0"/>
      <geometry>
        <box size="0.04 0.02 0.02"/>
      </geometry>
    </collision>
    <inertial>
      <origin xyz="0 0 0" rpy="0 0 0"/>
      <mass value="0.01"/>
      <inertia ixx="0.0001" ixy="0.0" ixz="0.0"
               iyy="0.0001" iyz="0.0"
               izz="0.0001"/>
    </inertial>
  </link>

  <!-- Laser Scanner Link -->
  <link name="laser">
    <visual>
      <origin xyz="0 0 0" rpy="0 0 0"/>
      <geometry>
        <cylinder length="0.04" radius="0.035"/>
      </geometry>
      <material name="black">
        <color rgba="0.1 0.1 0.1 1.0"/>
      </material>
    </visual>
    <collision>
      <origin xyz="0 0 0" rpy="0 0 0"/>
      <geometry>
        <cylinder length="0.04" radius="0.035"/>
      </geometry>
    </collision>
    <inertial>
      <origin xyz="0 0 0" rpy="0 0 0"/>
      <mass value="0.05"/>
      <inertia ixx="0.0001" ixy="0.0" ixz="0.0"
               iyy="0.0001" iyz="0.0"
               izz="0.0001"/>
    </inertial>
  </link>

  <!-- Joints -->
  <!-- Front Left wheel joint -->
  <joint name="front_left_wheel_joint" type="continuous">
    <parent link="base_link"/>
    <child link="front_left_wheel"/>
    <origin xyz="0.1 0.115 0" rpy="0 0 0"/>
    <axis xyz="0 1 0"/>
  </joint>

  <!-- Front Right wheel joint -->
  <joint name="front_right_wheel_joint" type="continuous">
    <parent link="base_link"/>
    <child link="front_right_wheel"/>
    <origin xyz="0.1 -0.115 0" rpy="0 0 0"/>
    <axis xyz="0 1 0"/>
  </joint>

  <!-- Rear Left wheel joint -->
  <joint name="rear_left_wheel_joint" type="continuous">
    <parent link="base_link"/>
    <child link="rear_left_wheel"/>
    <origin xyz="-0.1 0.115 0" rpy="0 0 0"/>
    <axis xyz="0 1 0"/>
  </joint>

  <!-- Rear Right wheel joint -->
  <joint name="rear_right_wheel_joint" type="continuous">
    <parent link="base_link"/>
    <child link="rear_right_wheel"/>
    <origin xyz="-0.1 -0.115 0" rpy="0 0 0"/>
    <axis xyz="0 1 0"/>
  </joint>

  <!-- Ultrasonic sensor joint -->
  <joint name="ultrasonic_joint" type="fixed">
    <parent link="base_link"/>
    <child link="ultrasonic_link"/>
    <origin xyz="0.15 0 0.08" rpy="0 0 0"/>
  </joint>

  <!-- Laser scanner joint -->
  <joint name="scan_joint" type="fixed">
    <parent link="base_link"/>
    <child link="laser"/>
    <origin xyz="0.1 0 0.15" rpy="0 0 0"/>
  </joint>

</robot>
