<?xml version="1.0"?>
<robot xmlns:xacro="http://www.ros.org/wiki/xacro" name="differential_drive_robot">

  <xacro:property name="wheel_radius" value="0.05"/>
  <xacro:property name="wheel_separation" value="0.24"/>

  <!-- Base Link -->
  <link name="base_link">
    <visual>
      <origin xyz="0 0 0.05" rpy="0 0 0"/>
      <geometry>
        <box size="0.3 0.2 0.1"/>
      </geometry>
      <material name="blue">
        <color rgba="0.0 0.0 0.8 1.0"/>
      </material>
    </visual>
    <collision>
      <origin xyz="0 0 0.05" rpy="0 0 0"/>
      <geometry>
        <box size="0.3 0.2 0.1"/>
      </geometry>
    </collision>
    <inertial>
      <mass value="2.0"/>
      <inertia ixx="0.01" ixy="0.0" ixz="0.0"
               iyy="0.01" iyz="0.0" izz="0.01"/>
    </inertial>
  </link>

  <!-- Left Wheel -->
  <link name="left_wheel">
    <visual>
      <origin xyz="0 0 0" rpy="1.5708 0 0"/>
      <geometry>
        <cylinder length="0.03" radius="${wheel_radius}"/>
      </geometry>
      <material name="red">
        <color rgba="0.8 0.0 0.0 1.0"/>
      </material>
    </visual>
    <collision>
      <origin xyz="0 0 0" rpy="1.5708 0 0"/>
      <geometry>
        <cylinder length="0.03" radius="${wheel_radius}"/>
      </geometry>
    </collision>
    <inertial>
      <mass value="0.2"/>
      <inertia ixx="0.001" ixy="0.0" ixz="0.0"
               iyy="0.001" iyz="0.0" izz="0.001"/>
    </inertial>
  </link>

  <!-- Right Wheel -->
  <link name="right_wheel">
    <visual>
      <origin xyz="0 0 0" rpy="1.5708 0 0"/>
      <geometry>
        <cylinder length="0.03" radius="${wheel_radius}"/>
      </geometry>
      <material name="red">
        <color rgba="0.8 0.0 0.0 1.0"/>
      </material>
    </visual>
    <collision>
      <origin xyz="0 0 0" rpy="1.5708 0 0"/>
      <geometry>
        <cylinder length="0.03" radius="${wheel_radius}"/>
      </geometry>
    </collision>
    <inertial>
      <mass value="0.2"/>
      <inertia ixx="0.001" ixy="0.0" ixz="0.0"
               iyy="0.001" iyz="0.0" izz="0.001"/>
    </inertial>
  </link>

  <!-- Sensor Links -->
  <link name="laser_link">
    <visual>
      <origin xyz="0 0 0" rpy="0 0 0"/>
      <geometry>
        <cylinder length="0.05" radius="0.03"/>
      </geometry>
      <material name="black">
        <color rgba="0.0 0.0 0.0 1.0"/>
      </material>
    </visual>
  </link>

  <link name="imu_link">
    <visual>
      <origin xyz="0 0 0" rpy="0 0 0"/>
      <geometry>
        <box size="0.02 0.02 0.01"/>
      </geometry>
      <material name="green">
        <color rgba="0.0 0.8 0.0 1.0"/>
      </material>
    </visual>
  </link>

  <link name="ultrasonic_link">
    <visual>
      <origin xyz="0 0 0" rpy="0 0 0"/>
      <geometry>
        <box size="0.04 0.02 0.02"/>
      </geometry>
      <material name="green">
        <color rgba="0.0 0.8 0.0 1.0"/>
      </material>
    </visual>
  </link>

  <!-- Joints -->
  <joint name="left_wheel_joint" type="continuous">
    <parent link="base_link"/>
    <child link="left_wheel"/>
    <origin xyz="0 ${wheel_separation/2} ${wheel_radius}" rpy="0 0 0"/>
    <axis xyz="0 1 0"/>
  </joint>

  <joint name="right_wheel_joint" type="continuous">
    <parent link="base_link"/>
    <child link="right_wheel"/>
    <origin xyz="0 ${-wheel_separation/2} ${wheel_radius}" rpy="0 0 0"/>
    <axis xyz="0 1 0"/>
  </joint>

  <joint name="laser_joint" type="fixed">
    <parent link="base_link"/>
    <child link="laser_link"/>
    <origin xyz="0.1 0 0.12" rpy="0 0 0"/>
  </joint>

  <joint name="imu_joint" type="fixed">
    <parent link="base_link"/>
    <child link="imu_link"/>
    <origin xyz="0 0 0.11" rpy="0 0 0"/>
  </joint>

  <joint name="ultrasonic_joint" type="fixed">
    <parent link="base_link"/>
    <child link="ultrasonic_link"/>
    <origin xyz="0.15 0 0.08" rpy="0 0 0"/>
  </joint>

  <!-- ROS2 Control -->
  <ros2_control name="DiffDriveHardware" type="system">
    <hardware>
      <plugin>robot_hardware/DiffDriveHardware</plugin>
      <param name="left_wheel_name">left_wheel</param>
      <param name="right_wheel_name">right_wheel</param>
      <param name="wheel_separation">${wheel_separation}</param>
      <param name="wheel_radius">${wheel_radius}</param>
    </hardware>
    
    <joint name="left_wheel_joint">
      <command_interface name="velocity">
        <param name="min">-10</param>
        <param name="max">10</param>
      </command_interface>
      <state_interface name="position"/>
      <state_interface name="velocity"/>
    </joint>
    
    <joint name="right_wheel_joint">
      <command_interface name="velocity">
        <param name="min">-10</param>
        <param name="max">10</param>
      </command_interface>
      <state_interface name="position"/>
      <state_interface name="velocity"/>
    </joint>
  </ros2_control>

  <!-- Gazebo simulation plugins (for testing) -->
  <gazebo>
    <plugin filename="libgazebo_ros2_control.so" name="gazebo_ros2_control">
      <parameters>$(find robot_description)/config/robot_hardware.yaml</parameters>
    </plugin>
  </gazebo>

</robot>
